<!DOCTYPE html>
<html lang="en">
  <head>
    <meta charset="UTF-8" />
    <meta http-equiv="X-UA-Compatible" content="IE=edge" />
    <meta name="viewport" content="width=device-width, initial-scale=1.0" />
    <title>Document</title>
  </head>
  <body>
    <script>
      const delay = (f, time = 0) => (value) =>setTimeout(() => f(value), time);
      const isFunction = (obj) => typeof obj === "function";
      const toString = Object.prototype.toString;
      const isObject = (obj) => toString.call(obj) === "[object Object]";
      const isThenable = (obj) =>(isObject(obj) || isFunction(obj)) && "then" in obj;
      const isPromise = (promise) => promise instanceof Promise;

      /**
        1. Promise 有 3 个状态：pending、fulfilled、rejected
          * pending：Promise 可以切换到 fulfilled 或者 rejected 状态
          * fulfilled：不能迁移到其他状态，必须有个不可变的 value
          * rejected：不能迁移到其他状态，必须有个不可变的 reason
      */

      const PENDING = Symbol("pending");
      const FULFILLED = Symbol("fulfilled");
      const REJECTED = Symbol("rejected");

      const handleCallBack = (handler, state, result) => {
        let { onFulfilled, onRejected, resolve, reject } = handler;
        try {
          // 3.6.4 判断 onFulfilled 是否为函数
          if (state === FULFILLED) {
            // 3.6.5 如果是，将它的返回值作为下一个 Promise 的 result
            // 3.6.6 如果不是，直接以当前 Promise 的 result 作为下一个 Promise 的 result
            isFunction(onFulfilled) ? resolve(onFulfilled(result)) : resolve(result);
          } else if (state === REJECTED) {
            isFunction(onRejected) ? resolve(onRejected(result)) : reject(result);
          }
        } catch (error) {
          reject(error);
        }
      };

      const handleCallBacks = delay((promise) => {
        let { callbacks, state, result } = promise;
        while (callbacks.length) {
          handleCallBack(callbacks.shift(), state, result);
        }
      });

      const transition = (promise, state, result) => {
        // 2.3 状态一旦不是 pending，就不允许再次转换
        if (promise.state !== PENDING) return;
        // 2.3.1 如果是 pending，那么就就该成对应的 state 和 result
        promise.state = state;
        promise.result = result;
        handleCallBacks(promise);
      };

      // 2.6 一些特殊的 value 被 resolve 时，要做特殊处理
      const resolvePromise = (promise, value, onFulfilled, onRejected) => {
        // 2.6.1 如果 value 是当前 Promise 本身，就抛出 TypeError 错误
        if (value === promise) {
          let reason = new TypeError("Can not fufill promise with itself");
          return onRejected(reason);
        }
        // 2.6.2 如果 value 是另一个 Promise，那么沿用当前的 state 和 result 状态
        if (value instanceof Promise) {
          return value.then(onFulfilled, onRejected);
        }
        // 2.6.3 如果 result 是一个 thenable 对象。
        // 先去 then 函数，再 call then 函数，重新进入 The Promise resolution procedure 过程
        if (isThenable(value)) {
          try {
            let then = value.then;
            if (isFunction(then)) {
              return new Promise(then.bind(value)).then(
                onFulfilled,
                onRejected
              );
            }
          } catch (error) {
            return onRejected(error);
          }
        }
        // 2.6.4 若都不是，直接 resolve result
        onFulfilled(value);
      };

      function Promise(f) {
        this.state = PENDING;
        this.callbacks = [];
        // 2.2 构造 onFulfilled 来切换到 fulfilled，构造 onRejected 来切换到 rejected 状态
        let onFulfilled = (value) => transition(this, FULFILLED, value);
        let onRejected = (reason) => transition(this, REJECTED, reason);
        // 2.3 配合 ignore 这个 flag，保证 resolve/reject 只有一次调用作用
        // let ignore = false;
        let resolve = (value) => {
          // if (ignore) return;
          // ignore = true;
          resolvePromise(this, value, onFulfilled, onRejected);
        };
        let reject = (reason) => {
          // if (ignore) return;
          // ignore = true;
          onRejected(reason);
        };
        try {
          // 2.6.1 将 resolve 和 reject 作为参数传入 f 函数，方便调用
          f(resolve, reject);
        } catch (error) {
          // 2.6.2 如果 f 函数执行报错，那么错误就作为 reject 的 reason 来用
          reject(error);
        }
      }
      Promise.prototype.then = function (onFulfilled, onRejected) {
        // 3.2 .then() 方法必须返回 Promise，所以需要 return 一个出去
        return new Promise((resolve, reject) => {
          this.callbacks.push({ onFulfilled, onRejected, resolve, reject });
          this.state !== PENDING && handleCallBacks(this);
        });
      };

      Promise.prototype.catch = function (onRejected) {
        return this.then(null, onRejected);
      };
      
      const promise = new Promise((resolve, reject) => {
        setTimeout(() => {
          console.log(1);
          // reject(5);
          resolve(7);
        }, 1000);
      });

      promise
        .then((res) => {
          console.log("res 1：", res);
          return 3;
        })
        .then((res) => {
          console.log("res 2：", res);
        }).catch(err => {
          console.log('err', err)
        })
    </script>
  </body>
</html>
